<?xml version="1.0" encoding="UTF-8"?>
<testng-results skipped="3" failed="1" total="10" passed="6">
  <reporter-output>
  </reporter-output>
  <suite name="Default suite" duration-ms="128118" started-at="2016-07-05T07:17:01Z" finished-at="2016-07-05T07:19:09Z">
    <groups>
    </groups>
    <test name="Default test" duration-ms="128118" started-at="2016-07-05T07:17:01Z" finished-at="2016-07-05T07:19:09Z">
      <class name="GithubAutomation.AppTest">
        <test-method status="PASS" signature="beforTest()[pri:0, instance:GithubAutomation.AppTest@724af044]" name="beforTest" is-config="true" duration-ms="81848" started-at="2016-07-05T12:47:01Z" finished-at="2016-07-05T12:48:23Z">
          <reporter-output>
          </reporter-output>
        </test-method> <!-- beforTest -->
        <test-method status="PASS" signature="testOne()[pri:0, instance:GithubAutomation.AppTest@724af044]" name="testOne" duration-ms="11917" started-at="2016-07-05T12:48:23Z" finished-at="2016-07-05T12:48:35Z">
          <reporter-output>
          </reporter-output>
        </test-method> <!-- testOne -->
        <test-method status="PASS" signature="testTwo()[pri:0, instance:GithubAutomation.AppTest@724af044]" name="testTwo" duration-ms="1475" started-at="2016-07-05T12:48:35Z" depends-on-methods="GithubAutomation.AppTest.testOne" finished-at="2016-07-05T12:48:36Z">
          <reporter-output>
          </reporter-output>
        </test-method> <!-- testTwo -->
        <test-method status="PASS" signature="testThree()[pri:0, instance:GithubAutomation.AppTest@724af044]" name="testThree" duration-ms="2486" started-at="2016-07-05T12:48:36Z" depends-on-methods="GithubAutomation.AppTest.testTwo" finished-at="2016-07-05T12:48:39Z">
          <reporter-output>
          </reporter-output>
        </test-method> <!-- testThree -->
        <test-method status="PASS" signature="testFour()[pri:0, instance:GithubAutomation.AppTest@724af044]" name="testFour" duration-ms="6226" started-at="2016-07-05T12:48:39Z" depends-on-methods="GithubAutomation.AppTest.testThree" finished-at="2016-07-05T12:48:45Z">
          <reporter-output>
          </reporter-output>
        </test-method> <!-- testFour -->
        <test-method status="PASS" signature="testFive()[pri:0, instance:GithubAutomation.AppTest@724af044]" name="testFive" duration-ms="8548" started-at="2016-07-05T12:48:45Z" depends-on-methods="GithubAutomation.AppTest.testFour" finished-at="2016-07-05T12:48:53Z">
          <reporter-output>
          </reporter-output>
        </test-method> <!-- testFive -->
        <test-method status="PASS" signature="testSix()[pri:0, instance:GithubAutomation.AppTest@724af044]" name="testSix" duration-ms="1207" started-at="2016-07-05T12:48:53Z" depends-on-methods="GithubAutomation.AppTest.testFive" finished-at="2016-07-05T12:48:55Z">
          <reporter-output>
          </reporter-output>
        </test-method> <!-- testSix -->
        <test-method status="FAIL" signature="testSeven()[pri:0, instance:GithubAutomation.AppTest@724af044]" name="testSeven" duration-ms="14377" started-at="2016-07-05T12:48:55Z" depends-on-methods="GithubAutomation.AppTest.testSix" finished-at="2016-07-05T12:49:09Z">
          <exception class="java.lang.AssertionError">
            <message>
              <![CDATA[expected [0] but found [1]]]>
            </message>
            <full-stacktrace>
              <![CDATA[java.lang.AssertionError: expected [0] but found [1]
	at org.testng.Assert.fail(Assert.java:94)
	at org.testng.Assert.failNotEquals(Assert.java:513)
	at org.testng.Assert.assertEqualsImpl(Assert.java:135)
	at org.testng.Assert.assertEquals(Assert.java:116)
	at org.testng.Assert.assertEquals(Assert.java:389)
	at org.testng.Assert.assertEquals(Assert.java:399)
	at GithubAutomation.AppTest.testSeven(AppTest.java:85)
	at sun.reflect.NativeMethodAccessorImpl.invoke0(Native Method)
	at sun.reflect.NativeMethodAccessorImpl.invoke(NativeMethodAccessorImpl.java:62)
	at sun.reflect.DelegatingMethodAccessorImpl.invoke(DelegatingMethodAccessorImpl.java:43)
	at java.lang.reflect.Method.invoke(Method.java:498)
	at org.testng.internal.MethodInvocationHelper.invokeMethod(MethodInvocationHelper.java:86)
	at org.testng.internal.Invoker.invokeMethod(Invoker.java:646)
	at org.testng.internal.Invoker.invokeTestMethod(Invoker.java:823)
	at org.testng.internal.Invoker.invokeTestMethods(Invoker.java:1131)
	at org.testng.internal.TestMethodWorker.invokeTestMethods(TestMethodWorker.java:129)
	at org.testng.internal.TestMethodWorker.run(TestMethodWorker.java:112)
	at org.testng.TestRunner.privateRun(TestRunner.java:778)
	at org.testng.TestRunner.run(TestRunner.java:632)
	at org.testng.SuiteRunner.runTest(SuiteRunner.java:366)
	at org.testng.SuiteRunner.runSequentially(SuiteRunner.java:361)
	at org.testng.SuiteRunner.privateRun(SuiteRunner.java:319)
	at org.testng.SuiteRunner.run(SuiteRunner.java:268)
	at org.testng.SuiteRunnerWorker.runSuite(SuiteRunnerWorker.java:52)
	at org.testng.SuiteRunnerWorker.run(SuiteRunnerWorker.java:86)
	at org.testng.TestNG.runSuitesSequentially(TestNG.java:1225)
	at org.testng.TestNG.runSuitesLocally(TestNG.java:1150)
	at org.testng.TestNG.runSuites(TestNG.java:1075)
	at org.testng.TestNG.run(TestNG.java:1047)
	at org.testng.remote.AbstractRemoteTestNG.run(AbstractRemoteTestNG.java:126)
	at org.testng.remote.RemoteTestNG.initAndRun(RemoteTestNG.java:137)
	at org.testng.remote.RemoteTestNG.main(RemoteTestNG.java:58)
]]>
            </full-stacktrace>
          </exception> <!-- java.lang.AssertionError -->
          <reporter-output>
          </reporter-output>
        </test-method> <!-- testSeven -->
        <test-method status="SKIP" signature="testEight()[pri:0, instance:GithubAutomation.AppTest@724af044]" name="testEight" duration-ms="0" started-at="2016-07-05T12:49:09Z" depends-on-methods="GithubAutomation.AppTest.testSeven" finished-at="2016-07-05T12:49:09Z">
          <exception class="java.lang.Throwable">
            <message>
              <![CDATA[Method AppTest.testEight()[pri:0, instance:GithubAutomation.AppTest@724af044] depends on not successfully finished methods]]>
            </message>
            <full-stacktrace>
              <![CDATA[java.lang.Throwable: Method AppTest.testEight()[pri:0, instance:GithubAutomation.AppTest@724af044] depends on not successfully finished methods
	at org.testng.internal.Invoker.invokeTestMethods(Invoker.java:1040)
	at org.testng.internal.TestMethodWorker.invokeTestMethods(TestMethodWorker.java:129)
	at org.testng.internal.TestMethodWorker.run(TestMethodWorker.java:112)
	at org.testng.TestRunner.privateRun(TestRunner.java:778)
	at org.testng.TestRunner.run(TestRunner.java:632)
	at org.testng.SuiteRunner.runTest(SuiteRunner.java:366)
	at org.testng.SuiteRunner.runSequentially(SuiteRunner.java:361)
	at org.testng.SuiteRunner.privateRun(SuiteRunner.java:319)
	at org.testng.SuiteRunner.run(SuiteRunner.java:268)
	at org.testng.SuiteRunnerWorker.runSuite(SuiteRunnerWorker.java:52)
	at org.testng.SuiteRunnerWorker.run(SuiteRunnerWorker.java:86)
	at org.testng.TestNG.runSuitesSequentially(TestNG.java:1225)
	at org.testng.TestNG.runSuitesLocally(TestNG.java:1150)
	at org.testng.TestNG.runSuites(TestNG.java:1075)
	at org.testng.TestNG.run(TestNG.java:1047)
	at org.testng.remote.AbstractRemoteTestNG.run(AbstractRemoteTestNG.java:126)
	at org.testng.remote.RemoteTestNG.initAndRun(RemoteTestNG.java:137)
	at org.testng.remote.RemoteTestNG.main(RemoteTestNG.java:58)
]]>
            </full-stacktrace>
          </exception> <!-- java.lang.Throwable -->
          <reporter-output>
          </reporter-output>
        </test-method> <!-- testEight -->
        <test-method status="SKIP" signature="testNine()[pri:0, instance:GithubAutomation.AppTest@724af044]" name="testNine" duration-ms="0" started-at="2016-07-05T12:49:09Z" depends-on-methods="GithubAutomation.AppTest.testEight" finished-at="2016-07-05T12:49:09Z">
          <exception class="java.lang.Throwable">
            <message>
              <![CDATA[Method AppTest.testNine()[pri:0, instance:GithubAutomation.AppTest@724af044] depends on not successfully finished methods]]>
            </message>
            <full-stacktrace>
              <![CDATA[java.lang.Throwable: Method AppTest.testNine()[pri:0, instance:GithubAutomation.AppTest@724af044] depends on not successfully finished methods
	at org.testng.internal.Invoker.invokeTestMethods(Invoker.java:1040)
	at org.testng.internal.TestMethodWorker.invokeTestMethods(TestMethodWorker.java:129)
	at org.testng.internal.TestMethodWorker.run(TestMethodWorker.java:112)
	at org.testng.TestRunner.privateRun(TestRunner.java:778)
	at org.testng.TestRunner.run(TestRunner.java:632)
	at org.testng.SuiteRunner.runTest(SuiteRunner.java:366)
	at org.testng.SuiteRunner.runSequentially(SuiteRunner.java:361)
	at org.testng.SuiteRunner.privateRun(SuiteRunner.java:319)
	at org.testng.SuiteRunner.run(SuiteRunner.java:268)
	at org.testng.SuiteRunnerWorker.runSuite(SuiteRunnerWorker.java:52)
	at org.testng.SuiteRunnerWorker.run(SuiteRunnerWorker.java:86)
	at org.testng.TestNG.runSuitesSequentially(TestNG.java:1225)
	at org.testng.TestNG.runSuitesLocally(TestNG.java:1150)
	at org.testng.TestNG.runSuites(TestNG.java:1075)
	at org.testng.TestNG.run(TestNG.java:1047)
	at org.testng.remote.AbstractRemoteTestNG.run(AbstractRemoteTestNG.java:126)
	at org.testng.remote.RemoteTestNG.initAndRun(RemoteTestNG.java:137)
	at org.testng.remote.RemoteTestNG.main(RemoteTestNG.java:58)
]]>
            </full-stacktrace>
          </exception> <!-- java.lang.Throwable -->
          <reporter-output>
          </reporter-output>
        </test-method> <!-- testNine -->
        <test-method status="SKIP" signature="testTen()[pri:0, instance:GithubAutomation.AppTest@724af044]" name="testTen" duration-ms="0" started-at="2016-07-05T12:49:09Z" depends-on-methods="GithubAutomation.AppTest.testNine" finished-at="2016-07-05T12:49:09Z">
          <exception class="java.lang.Throwable">
            <message>
              <![CDATA[Method AppTest.testTen()[pri:0, instance:GithubAutomation.AppTest@724af044] depends on not successfully finished methods]]>
            </message>
            <full-stacktrace>
              <![CDATA[java.lang.Throwable: Method AppTest.testTen()[pri:0, instance:GithubAutomation.AppTest@724af044] depends on not successfully finished methods
	at org.testng.internal.Invoker.invokeTestMethods(Invoker.java:1040)
	at org.testng.internal.TestMethodWorker.invokeTestMethods(TestMethodWorker.java:129)
	at org.testng.internal.TestMethodWorker.run(TestMethodWorker.java:112)
	at org.testng.TestRunner.privateRun(TestRunner.java:778)
	at org.testng.TestRunner.run(TestRunner.java:632)
	at org.testng.SuiteRunner.runTest(SuiteRunner.java:366)
	at org.testng.SuiteRunner.runSequentially(SuiteRunner.java:361)
	at org.testng.SuiteRunner.privateRun(SuiteRunner.java:319)
	at org.testng.SuiteRunner.run(SuiteRunner.java:268)
	at org.testng.SuiteRunnerWorker.runSuite(SuiteRunnerWorker.java:52)
	at org.testng.SuiteRunnerWorker.run(SuiteRunnerWorker.java:86)
	at org.testng.TestNG.runSuitesSequentially(TestNG.java:1225)
	at org.testng.TestNG.runSuitesLocally(TestNG.java:1150)
	at org.testng.TestNG.runSuites(TestNG.java:1075)
	at org.testng.TestNG.run(TestNG.java:1047)
	at org.testng.remote.AbstractRemoteTestNG.run(AbstractRemoteTestNG.java:126)
	at org.testng.remote.RemoteTestNG.initAndRun(RemoteTestNG.java:137)
	at org.testng.remote.RemoteTestNG.main(RemoteTestNG.java:58)
]]>
            </full-stacktrace>
          </exception> <!-- java.lang.Throwable -->
          <reporter-output>
          </reporter-output>
        </test-method> <!-- testTen -->
      </class> <!-- GithubAutomation.AppTest -->
    </test> <!-- Default test -->
  </suite> <!-- Default suite -->
</testng-results>
